Workbook

Sheet Hướng dẫn
B2: FER202 — AI Log Template | Project Nhóm
B3: Hướng dẫn sử dụng | FPT University
B5: 📌 MỤC ĐÍCH
B6: File này dùng để gì? | C6: Ghi lại nhật ký sử dụng AI của nhóm trong suốt project môn FER202 — theo từng tuần.
B7: Ai điền? | C7: Mỗi thành viên tự điền phần của mình vào các bảng của tuần tương ứng. Trưởng nhóm tổng hợp và upload.
B8: Nộp khi nào? | C8: Cuối mỗi tuần (hoặc theo deadline giảng viên). Một file duy nhất cho cả học kỳ.
B10: 📁 CÁC SHEET TRONG FILE
B11: Thông tin nhóm | C11: Điền 1 lần đầu học kỳ: tên nhóm, MSSV, phân công, mô tả project.
B12: Week_01 → Week_10 | C12: Mỗi tuần có 4 bảng: AI_Audit_Log, Changelog, Prompts, Reflection.
B13: Summary | C13: Tổng hợp tự động (công thức) số lần dùng AI, mức hỗ trợ theo từng tuần/thành viên.
B15: 📝 4 BẢNG TRONG MỖI TUẦN
B16: BẢNG 1 — AI_AUDIT_LOG | C16: Ghi mỗi lần dùng AI: ngày, ai dùng, tool, mục đích, mức hỗ trợ, đã chỉnh sửa gì, kiểm chứng.
B17: BẢNG 2 — CHANGELOG | C17: Ghi thay đổi project trong tuần (Added / Changed / Fixed / Removed). Không bắt buộc gắn với AI.
B18: BẢNG 3 — PROMPTS | C18: Ghi chi tiết từng prompt quan trọng đã dùng: nội dung, kết quả AI trả về, cách nhóm sử dụng/chỉnh sửa.
B19: BẢNG 4 — REFLECTION | C19: Mỗi thành viên viết 1 block suy ngẫm cá nhân cuối tuần (đã làm gì, AI hỗ trợ ra sao, điểm chưa tốt).
B21: ✅ QUY ƯỚC
B22: Cột TV | C22: Dùng ký hiệu A / B / C / D / E (khớp với bảng Thông tin nhóm).
B23: Mức hỗ trợ AI | C23: Low = AI gợi ý nhỏ | Medium = AI đóng góp đáng kể | High = AI tạo phần lớn nội dung
B24: Loại Changelog | C24: Added = thêm mới | Changed = cải tiến | Fixed = sửa lỗi | Removed = xóa bỏ
B25: (*) bắt buộc | C25: Các cột đánh dấu (*) là bắt buộc phải điền.

Sheet Thông tin nhóm
B2: THÔNG TIN NHÓM — FER202
B3: 📋 Thông tin lớp
B4: Mã lớp học | C4: FER202_SE20A07
B5: Giảng viên | C5: Lê Thị Bích Tra — traltb@fe.edu.vn
B6: Học kỳ / Năm học | C6: SU26
B7: Tên nhóm | C7: FJMS
B8: Số thành viên | C8: 3
B10: 👥 Danh sách thành viên
B11: Ký hiệu (*) | C11: Họ và tên (*) | D11: MSSV (*) | E11: Email (*) | F11: Vai trò | G11: Ghi chú
B12: A | C12: Phan Hữu Linh | D12: DE191102 | E12: benphilip11234@gmail.com | F12: Trưởng nhóm
B13: B | C13: Nguyễn Đăng Khang Huy | D13: DE190258 | E13: vietnamnhungchuyendi@gmail.com | F13: Thành viên
B14: C | C14: Kiều Thị Kim Thoa | D14: DE190363 | E14: Thoakieu309@gmail.com | F14: Thành viên
B15: D | F15: Thành viên
B16: E | F16: Thành viên
B18: 💡 Mô tả dự án
B19: Tên hệ thống | C19: Freelancer Job Matching System (FJMS)
B20: Mô tả ngắn | C20: FJMS là nền tảng kết nối giữa Freelancer và Employer, cho phép đăng dự án, tìm kiếm ứng viên phù hợp, gửi đề xuất (Proposal), quản lý hợp đồng, thanh toán ký quỹ (Escrow), nhắn tin thời gian thực và đánh giá sau khi hoàn thành dự án. Hệ thống tích hợp AI Chatbot hỗ trợ người dùng và sử dụng VNPay để xử lý thanh toán trực tuyến an toàn.
B21: Công nghệ sử dụng | C21: Frontend: ReactJS, TailwindCSS, Axios, React Router DOM Backend: NodeJS, ExpressJS, JWT Authentication, Socket.io Database: Microsoft SQL Server External Services: VNPay API, Email Service (OTP Verification)
B22: Link repo (GitHub/GitLab) | C22: https://github.com/SUMMER2026SE/swp391-rbl-project-team_7-1.git
B23: Link Jira
B24: Link demo

Sheet Week_01
B2: WEEK 01 — Nhật ký AI & Project
B3: Mỗi thành viên dùng ký hiệu A/B/C/D/E ở cột TV. Cột (*) bắt buộc điền. Lưu file sau khi điền xong.
B5: 📋 BẢNG 1: Nhật ký sử dụng AI (AI_AUDIT_LOG)
B6: Ghi mỗi lần dùng AI vào 1 dòng. Mức hỗ trợ: Low = AI gợi ý nhỏ | Medium = AI đóng góp nhiều | High = AI tạo phần lớn
B7: Ngày (*) | C7: TV (*) | D7: Công cụ AI (*) | E7: Mục đích sử dụng (*) | F7: File ảnh hưởng | G7: Mức hỗ trợ (*) | H7: Đã chỉnh sửa gì? | I7: Kiểm chứng
B8: 2026-06-23 | C8: A | D8: Gemini | E8: Khởi tạo Vite project, cấu hình thư mục dự án và cài đặt bootstrap, router, axios | F8: package.json, src/ | G8: High | H8: Tạo dự án React 19 + Vite, thiết lập 5 folder src/components, pages... | I8: https://github.com/fudn-traltb-su26/rbl-fer202-theotuan-team-fjms/commit/cc82121
B9: 2026-06-23 | C9: A | D9: Gemini | E9: Vẽ sơ đồ Component Tree cho dự án FJMS | F9: Week01/docs/component-tree.png | G9: Medium | H9: Thiết lập sơ đồ phân cấp cho các component App, Header, Banner, CategoryList, ProjectGrid, ProjectCard | I9: File component-tree.png
B10: 2026-06-23 | C10: A | D10: gemini | E10: Viết README.md tài liệu hướng dẫn setup dự án | F10: Week01/fjms-frontend/README.md | G10: Medium | H10: Tạo tài liệu đặc tả các folder và các bước chạy npm install/run dev | I10: File README.md
B17: 📝 BẢNG 2: Nhật ký thay đổi project (CHANGELOG)
B18: Added = thêm mới | Changed = cải tiến | Fixed = sửa lỗi | Removed = xóa bỏ
B19: Loại (*) | C19: TV (*) | D19: Mô tả thay đổi (*) | G19: File liên quan | I19: Ghi chú
B20: Added — Thêm mới
C21: A | D21: Khởi tạo repo git và setup ban đầu dự án ReactJS + Vite | G21: package.json, src/ | I21: Khởi tạo thành công
C22: B | D22: Tích hợp file db.json chứa 8 dự án tuyển dụng và 5 danh mục ngành nghề của FJMS | G22: db.json | I22: Phục vụ cho việc chạy thử json-server
B24: Changed — Cải tiến
C25: A | D25: Đồng bộ hóa các đường dẫn và cập nhật file TODO.md theo cấu trúc 3 thành viên | G25: TODO.md | I25: Đồng bộ hoàn tất các tuần
B28: Fixed — Sửa lỗi
B32: Removed — Xóa bỏ
B37: 💡 BẢNG 3: Nhật ký Prompt AI (PROMPTS)
B38: Mỗi prompt quan trọng ghi 1 block gồm 4 dòng. Ghi rõ prompt đã dùng, kết quả, cách nhóm sử dụng, và kiểm chứng.
B39: Prompt # | C39: TV | D39: Công cụ AI | E39: Prompt đã dùng (nguyên văn) (*)
B40: Prompt #1 (A — Antigravity) | E40: Nhờ AI hướng dẫn cách cài đặt và cấu trúc một dự án ReactJS dùng Vite cho môn FER202, có cài thêm Bootstrap, Axios và Router DOM. Chỉ cách chia folder sao cho sạch và dễ quản lý nhóm.
B41: Kết quả AI trả về và vấn đề gặp phải: | E41: AI nó chỉ các câu lệnh npm cài đặt rất nhanh, và đưa ra cấu trúc thư mục chuẩn. Tuy nhiên, nó bị lỗi thời khi vẫn khuyên dùng Create React App (CRA) dù cái này đã bị deprecated từ lâu. Ngoài ra, nó gợi ý nhét cả Redux và Context cùng lúc ngay từ tuần đầu làm code rất rối và thừa thãi.
B42: Nhóm đã chỉnh sửa / sử dụng như thế nào: | E42: Nhóm quyết định bỏ qua gợi ý CRA, dùng Vite chạy cho nhẹ. Thư mục src chia thành các folder con: components, pages, hooks, services, context. Chưa tạo folder store/redux vì tuần 1 chưa cần quản lý state phức tạp đến thế.
B43: Kiểm chứng (test pass/fail, kết quả đúng không): | E43: Chạy thử npm run dev thấy lên trang mặc định của Vite, vào tab Console kiểm tra không thấy báo lỗi đỏ nào.
B44: Prompt #2
B45: Kết quả AI trả về và vấn đề gặp phải:
B46: Nhóm đã chỉnh sửa / sử dụng như thế nào:
B47: Kiểm chứng (test pass/fail, kết quả đúng không):
B48: Prompt #3
B49: Kết quả AI trả về và vấn đề gặp phải:
B50: Nhóm đã chỉnh sửa / sử dụng như thế nào:
B51: Kiểm chứng (test pass/fail, kết quả đúng không):
B52: Prompt #4
B53: Kết quả AI trả về và vấn đề gặp phải:
B54: Nhóm đã chỉnh sửa / sử dụng như thế nào:
B55: Kiểm chứng (test pass/fail, kết quả đúng không):
... B59: Thành viên A — Trưởng nhóm
B60: Đã làm gì trong tuần này? (*) | E60: Setup dự án Vite, chia folder src, cài bootstrap, router, axios. Viết README.md và vẽ sơ đồ component tree đơn giản.
B61: AI đã hỗ trợ như thế nào? | E61: Hỏi AI để tham khảo cách chia thư mục và cấu trúc file. Tiết kiệm được thời gian gõ code cấu trúc thô ban đầu.
...

Sheet Week_02
B2: WEEK 01 — Nhật ký AI & Project
B3: Mỗi thành viên dùng ký hiệu A/B/C/D/E ở cột TV. Cột (*) bắt buộc điền. Lưu file sau khi điền xong.
B5: 📋 BẢNG 1: Nhật ký sử dụng AI (AI_AUDIT_LOG)
B6: Ghi mỗi lần dùng AI vào 1 dòng. Mức hỗ trợ: Low = AI gợi ý nhỏ | Medium = AI đóng góp nhiều | High = AI tạo phần lớn
B7: Ngày (*) | C7: TV (*) | D7: Công cụ AI (*) | E7: Mục đích sử dụng (*) | F7: File ảnh hưởng | G7: Mức hỗ trợ (*) | H7: Đã chỉnh sửa gì? | I7: Kiểm chứng
B8: 2026-06-24 | C8: A | D8: Gemini | E8: Tạo giao diện Header.jsx tĩnh cho sàn FJMS | F8: src/components/Header.jsx | G8: Medium | H8: Tạo thanh Navbar với Logo, các link Trang chủ, Tìm việc, Dự án đã lưu, Dashboard và icon giỏ hàng | I8: File Header.jsx
B9: 2026-06-24 | C9: A | D9: Gemini | E9: Tạo giao diện Footer.jsx có năm hiện tại động | F9: src/components/Footer.jsx | G9: Low | H9: Code chân trang với năm bản quyền tự động cập nhật qua new Date().getFullYear() | I9: File Footer.jsx
B17: 📝 BẢNG 2: Nhật ký thay đổi project (CHANGELOG)
B18: Added = thêm mới | Changed = cải tiến | Fixed = sửa lỗi | Removed = xóa bỏ
B19: Loại (*) | C19: TV (*) | D19: Mô tả thay đổi (*) | G19: File liên quan | I19: Ghi chú
B20: Added — Thêm mới
C21: A | D21: Tạo mới components Header.jsx và Footer.jsx tĩnh cho dự án | G21: src/components/Header.jsx, src/components/Footer.jsx | I21: Header có navbar và footer có năm tự động
C22: A | D22: Thêm CSS cơ bản trong index.css để reset margin/padding và set màu chủ đạo Emerald green cho FJMS | G22: src/index.css | I22: Style màu thương hiệu
B24: Changed — Cải tiến
B28: Fixed — Sửa lỗi
B32: Removed — Xóa bỏ
B37: 💡 BẢNG 3: Nhật ký Prompt AI (PROMPTS)
B38: Mỗi prompt quan trọng ghi 1 block gồm 4 dòng. Ghi rõ prompt đã dùng, kết quả, cách nhóm sử dụng, và kiểm chứng.
B39: Prompt # | C39: TV | D39: Công cụ AI | E39: Prompt đã dùng (nguyên văn) (*)
B40: Prompt #1 (A — Gemini) | E40: Viết giùm code component Header.jsx bằng React 19 hiển thị thanh Navbar. Có logo FJMS Marketplace ở bên trái, giữa là các link trang chủ, tìm việc, dự án đã lưu, dashboard. Bên phải có icon giỏ hàng.
B41: Kết quả AI trả về và vấn đề gặp phải: | E41: AI sinh ra code HTML và CSS inline khá dài dòng. Giao diện nhìn tạm ổn nhưng nó xài thẻ <a> cho các link điều hướng làm trang bị load lại mỗi khi click, mất tính chất Single Page App.
B42: Nhóm đã chỉnh sửa / sử dụng như thế nào: | E42: Nhóm thay toàn bộ thẻ <a> thành component <Link> và <NavLink> từ thư viện react-router-dom để chuyển trang không bị load lại. Đồng thời dọn bớt đống style inline nhét vào file CSS riêng.
B43: Kiểm chứng (test pass/fail, kết quả đúng không): | E43: Click thử giữa các tab trên Header thấy chuyển trang mượt, không bị xoay vòng tròn load lại trang.
B44: Prompt #2
B45: Kết quả AI trả về và vấn đề gặp phải:
B46: Nhóm đã chỉnh sửa / sử dụng như thế nào:
B47: Kiểm chứng (test pass/fail, kết quả đúng không):
B48: Prompt #3
B49: Kết quả AI trả về và vấn đề gặp phải:
B50: Nhóm đã chỉnh sửa / sử dụng như thế nào:
B51: Kiểm chứng (test pass/fail, kết quả đúng không):
B52: Prompt #4
B53: Kết quả AI trả về và vấn đề gặp phải:
B54: Nhóm đã chỉnh sửa / sử dụng như thế nào:
B55: Kiểm chứng (test pass/fail, kết quả đúng không):
... B59: Thành viên A — Trưởng nhóm
B60: Đã làm gì trong tuần này? (*) | E60: Code xong Header.jsx và Footer.jsx tĩnh cho dự án FJMS.
B61: AI đã hỗ trợ như thế nào? | E61: AI gen khung HTML và css mẫu cho Header/Footer nhanh, đỡ phải tự gõ từng thẻ.
B62: AI sai hoặc thiếu ở đâu? (*) | E62: (1) AI sử dụng các thẻ <a> thay vì Link làm app bị reload. (2) AI viết style dạng inline quá dài dòng trong JSX làm file code dài hơn 200 dòng, rất khó bảo trì.
B63: Khó khăn gặp phải | E63: Header bị lệch align giữa logo và menu, phải tự căn chỉnh lại flexbox.
...

Sheet Week_03
B2: WEEK 01 — Nhật ký AI & Project
B3: Mỗi thành viên dùng ký hiệu A/B/C/D/E ở cột TV. Cột (*) bắt buộc điền. Lưu file sau khi điền xong.
B5: 📋 BẢNG 1: Nhật ký sử dụng AI (AI_AUDIT_LOG)
B6: Ghi mỗi lần dùng AI vào 1 dòng. Mức hỗ trợ: Low = AI gợi ý nhỏ | Medium = AI đóng góp nhiều | High = AI tạo phần lớn
B7: Ngày (*) | C7: TV (*) | D7: Công cụ AI (*) | E7: Mục đích sử dụng (*) | F7: File ảnh hưởng | G7: Mức hỗ trợ (*) | H7: Đã chỉnh sửa gì? | I7: Kiểm chứng
B8: 2026-06-25 | C8: A | D8: Gemini | E8: Refactor ProjectCard.jsx để nhận dữ liệu qua props | F8: src/components/ProjectCard.jsx | G8: Medium | H8: Thay đổi dữ liệu hardcode thành các thuộc tính động từ project object (title, budget, category) | I8: File ProjectCard.jsx
B9: 2026-06-25 | C9: A | D9: Gemini | E9: Xử lý sự kiện onSaveProject qua props của ProjectCard | F9: src/components/ProjectCard.jsx | G9: Low | H9: Liên kết nút lưu dự án gọi đến callback handler từ component cha | I9: File ProjectCard.jsx
B17: 📝 BẢNG 2: Nhật ký thay đổi project (CHANGELOG)
B18: Added = thêm mới | Changed = cải tiến | Fixed = sửa lỗi | Removed = xóa bỏ
B19: Loại (*) | C19: TV (*) | D19: Mô tả thay đổi (*) | G19: File liên quan | I19: Ghi chú
B20: Added — Thêm mới
B24: Changed — Cải tiến
C25: A | D25: Refactor ProjectCard.jsx chuyển đổi từ dữ liệu hardcode sang props động | G25: src/components/ProjectCard.jsx | I25: Nhận project object và callback onSaveProject
C26: A | D26: Cập nhật App.jsx để truyền mảng PROJECTS mẫu xuống ProjectGrid làm dữ liệu đầu vào | G26: src/App.jsx | I26: Test luồng dữ liệu một chiều
B28: Fixed — Sửa lỗi
B32: Removed — Xóa bỏ
B37: 💡 BẢNG 3: Nhật ký Prompt AI (PROMPTS)
B38: Mỗi prompt quan trọng ghi 1 block gồm 4 dòng. Ghi rõ prompt đã dùng, kết quả, cách nhóm sử dụng, và kiểm chứng.
B39: Prompt # | C39: TV | D39: Công cụ AI | E39: Prompt đã dùng (nguyên văn) (*)
B40: Prompt #1 (A — Antigravity) | E40: Refactor component ProjectCard.jsx để nó nhận object project qua props chứ không hardcode nữa. Nút Lưu dự án thì gọi hàm onSaveProject từ component cha truyền xuống. Budget thì format dạng VND.
B41: Kết quả AI trả về và vấn đề gặp phải: | E41: AI viết hàm format tiền VND khá chuẩn bằng Intl.NumberFormat. Nhưng nó quên check điều kiện null của project object. Khi data chưa truyền xuống kịp thì app bị crash màn hình trắng xoá vì lỗi Cannot read properties of undefined.
B42: Nhóm đã chỉnh sửa / sử dụng như thế nào: | E42: Nhóm sửa lại bằng cách thêm toán tử optional chaining (project?.title, project?.budget) và set một project mặc định nếu props truyền vào bị rỗng.
B43: Kiểm chứng (test pass/fail, kết quả đúng không): | E43: Truyền thử project rỗng vào Card thấy không bị crash app nữa, hiển thị đúng budget định dạng VND.
B44: Prompt #2
B45: Kết quả AI trả về và vấn đề gặp phải:
B46: Nhóm đã chỉnh sửa / sử dụng như thế nào:
B47: Kiểm chứng (test pass/fail, kết quả đúng không):
B48: Prompt #3
B49: Kết quả AI trả về và vấn đề gặp phải:
B50: Nhóm đã chỉnh sửa / sử dụng như thế nào:
B51: Kiểm chứng (test pass/fail, kết quả đúng không):
B52: Prompt #4
B53: Kết quả AI trả về và vấn đề gặp phải:
B54: Nhóm đã chỉnh sửa / sử dụng như thế nào:
B55: Kiểm chứng (test pass/fail, kết quả đúng không):
... B59: Thành viên A — Trưởng nhóm
B60: Đã làm gì trong tuần này? (*) | E60: Refactor ProjectCard để truyền nhận props động, định dạng tiền tệ và nhận callback từ component cha.
B61: AI đã hỗ trợ như thế nào? | E61: AI hướng dẫn cách viết hàm format VND và destructing props nhanh gọn.
B62: AI sai hoặc thiếu ở đâu? (*) | E62: (1) AI không sử dụng optional chaining khi truy xuất các thuộc tính của project object dẫn đến lỗi crash. (2) AI gợi ý sai cú pháp hàm callback khi quên không bọc vào arrow function làm nó tự chạy liên tục khi render.
B63: Khó khăn gặp phải | E63: Lỗi render vòng lặp vô hạn ở hàm callback của nút Lưu dự án, mất cả buổi chiều để debug.
...

Sheet Week_04
B2: WEEK 01 — Nhật ký AI & Project
B3: Mỗi thành viên dùng ký hiệu A/B/C/D/E ở cột TV. Cột (*) bắt buộc điền. Lưu file sau khi điền xong.
B5: 📋 BẢNG 1: Nhật ký sử dụng AI (AI_AUDIT_LOG)
B6: Ghi mỗi lần dùng AI vào 1 dòng. Mức hỗ trợ: Low = AI gợi ý nhỏ | Medium = AI đóng góp nhiều | High = AI tạo phần lớn
B7: Ngày (*) | C7: TV (*) | D7: Công cụ AI (*) | E7: Mục đích sử dụng (*) | F7: File ảnh hưởng | G7: Mức hỗ trợ (*) | H7: Đã chỉnh sửa gì? | I7: Kiểm chứng
B17: 📝 BẢNG 2: Nhật ký thay đổi project (CHANGELOG)
B18: Added = thêm mới | Changed = cải tiến | Fixed = sửa lỗi | Removed = xóa bỏ
B19: Loại (*) | C19: TV (*) | D19: Mô tả thay đổi (*) | G19: File liên quan | I19: Ghi chú
B20: Added — Thêm mới
B24: Changed — Cải tiến
B28: Fixed — Sửa lỗi
B32: Removed — Xóa bỏ
B37: 💡 BẢNG 3: Nhật ký Prompt AI (PROMPTS)
B38: Mỗi prompt quan trọng ghi 1 block gồm 4 dòng. Ghi rõ prompt đã dùng, kết quả, cách nhóm sử dụng, và kiểm chứng.
B39: Prompt # | C39: TV | D39: Công cụ AI | E39: Prompt đã dùng (nguyên văn) (*)
B40: Prompt #1
B41: Kết quả AI trả về và vấn đề gặp phải:
B42: Nhóm đã chỉnh sửa / sử dụng như thế nào:
B43: Kiểm chứng (test pass/fail, kết quả đúng không):
B44: Prompt #2
B45: Kết quả AI trả về và vấn đề gặp phải:
B46: Nhóm đã chỉnh sửa / sử dụng như thế nào:
B47: Kiểm chứng (test pass/fail, kết quả đúng không):
B48: Prompt #3
B49: Kết quả AI trả về và vấn đề gặp phải:
B50: Nhóm đã chỉnh sửa / sử dụng như thế nào:
B51: Kiểm chứng (test pass/fail, kết quả đúng không):
... B59: Thành viên A — Trưởng nhóm
B60: Đã làm gì trong tuần này? (*) | E60: 💬 Liệt kê cụ thể: tính năng, test case, module, file...
B61: AI đã hỗ trợ như thế nào? | E61: 💬 Tóm tắt cách dùng AI: tool nào, việc gì, hiệu quả ra sao
B62: AI sai hoặc thiếu ở đâu? (*) | E62: 💬 ⚠️ Bắt buộc ≥ 2 ví dụ cụ thể về điểm AI chưa đúng/đủ
B63: Khó khăn gặp phải | E63: 💬 Kỹ thuật, nhóm, công cụ, môi trường...
B64: Nếu làm lại, sẽ cải thiện điều gì? | E64: 💬 Quy trình, cách dùng AI, phân công nhóm...
B66: Thành viên B — Thành viên
B67: Đã làm gì trong tuần này? (*) | E67: 💬 Liệt kê cụ thể: tính năng, test case, module, file...
B68: AI đã hỗ trợ như thế nào? | E68: 💬 Tóm tắt cách dùng AI: tool nào, việc gì, hiệu quả ra sao
B69: AI sai hoặc thiếu ở đâu? (*) | E69: 💬 ⚠️ Bắt buộc ≥ 2 ví dụ cụ thể về điểm AI chưa đúng/đủ
B70: Khó khăn gặp phải | E70: 💬 Kỹ thuật, nhóm, công cụ, môi trường...
B71: Nếu làm lại, sẽ cải thiện điều gì? | E71: 💬 Quy trình, cách dùng AI, phân công nhóm...
B73: Thành viên C — Thành viên
...

Sheet Week_05
B2: WEEK 01 — Nhật ký AI & Project
B3: Mỗi thành viên dùng ký hiệu A/B/C/D/E ở cột TV. Cột (*) bắt buộc điền. Lưu file sau khi điền xong.
B5: 📋 BẢNG 1: Nhật ký sử dụng AI (AI_AUDIT_LOG)
B6: Ghi mỗi lần dùng AI vào 1 dòng. Mức hỗ trợ: Low = AI gợi ý nhỏ | Medium = AI đóng góp nhiều | High = AI tạo phần lớn
B7: Ngày (*) | C7: TV (*) | D7: Công cụ AI (*) | E7: Mục đích sử dụng (*) | F7: File ảnh hưởng | G7: Mức hỗ trợ (*) | H7: Đã chỉnh sửa gì? | I7: Kiểm chứng
B17: 📝 BẢNG 2: Nhật ký thay đổi project (CHANGELOG)
B18: Added = thêm mới | Changed = cải tiến | Fixed = sửa lỗi | Removed = xóa bỏ
B19: Loại (*) | C19: TV (*) | D19: Mô tả thay đổi (*) | G19: File liên quan | I19: Ghi chú
B20: Added — Thêm mới
B24: Changed — Cải tiến
B28: Fixed — Sửa lỗi
B32: Removed — Xóa bỏ
B37: 💡 BẢNG 3: Nhật ký Prompt AI (PROMPTS)
B38: Mỗi prompt quan trọng ghi 1 block gồm 4 dòng. Ghi rõ prompt đã dùng, kết quả, cách nhóm sử dụng, và kiểm chứng.
B39: Prompt # | C39: TV | D39: Công cụ AI | E39: Prompt đã dùng (nguyên văn) (*)
B40: Prompt #1
B41: Kết quả AI trả về và vấn đề gặp phải:
B42: Nhóm đã chỉnh sửa / sử dụng như thế nào:
B43: Kiểm chứng (test pass/fail, kết quả đúng không):
B44: Prompt #2
B45: Kết quả AI trả về và vấn đề gặp phải:
B46: Nhóm đã chỉnh sửa / sử dụng như thế nào:
B47: Kiểm chứng (test pass/fail, kết quả đúng không):
B48: Prompt #3
B49: Kết quả AI trả về và vấn đề gặp phải:
B50: Nhóm đã chỉnh sửa / sử dụng như thế nào:
B51: Kiểm chứng (test pass/fail, kết quả đúng không):
... B59: Thành viên A — Trưởng nhóm
B60: Đã làm gì trong tuần này? (*) | E60: 💬 Liệt kê cụ thể: tính năng, test case, module, file...
B61: AI đã hỗ trợ như thế nào? | E61: 💬 Tóm tắt cách dùng AI: tool nào, việc gì, hiệu quả ra sao
B62: AI sai hoặc thiếu ở đâu? (*) | E62: 💬 ⚠️ Bắt buộc ≥ 2 ví dụ cụ thể về điểm AI chưa đúng/đủ
B63: Khó khăn gặp phải | E63: 💬 Kỹ thuật, nhóm, công cụ, môi trường...
B64: Nếu làm lại, sẽ cải thiện điều gì? | E64: 💬 Quy trình, cách dùng AI, phân công nhóm...
B66: Thành viên B — Thành viên
B67: Đã làm gì trong tuần này? (*) | E67: 💬 Liệt kê cụ thể: tính năng, test case, module, file...
B68: AI đã hỗ trợ như thế nào? | E68: 💬 Tóm tắt cách dùng AI: tool nào, việc gì, hiệu quả ra sao
B69: AI sai hoặc thiếu ở đâu? (*) | E69: 💬 ⚠️ Bắt buộc ≥ 2 ví dụ cụ thể về điểm AI chưa đúng/đủ
B70: Khó khăn gặp phải | E70: 💬 Kỹ thuật, nhóm, công cụ, môi trường...
B71: Nếu làm lại, sẽ cải thiện điều gì? | E71: 💬 Quy trình, cách dùng AI, phân công nhóm...
B73: Thành viên C — Thành viên
...

Sheet Week_06
B2: WEEK 01 — Nhật ký AI & Project
B3: Mỗi thành viên dùng ký hiệu A/B/C/D/E ở cột TV. Cột (*) bắt buộc điền. Lưu file sau khi điền xong.
B5: 📋 BẢNG 1: Nhật ký sử dụng AI (AI_AUDIT_LOG)
B6: Ghi mỗi lần dùng AI vào 1 dòng. Mức hỗ trợ: Low = AI gợi ý nhỏ | Medium = AI đóng góp nhiều | High = AI tạo phần lớn
B7: Ngày (*) | C7: TV (*) | D7: Công cụ AI (*) | E7: Mục đích sử dụng (*) | F7: File ảnh hưởng | G7: Mức hỗ trợ (*) | H7: Đã chỉnh sửa gì? | I7: Kiểm chứng
B17: 📝 BẢNG 2: Nhật ký thay đổi project (CHANGELOG)
B18: Added = thêm mới | Changed = cải tiến | Fixed = sửa lỗi | Removed = xóa bỏ
B19: Loại (*) | C19: TV (*) | D19: Mô tả thay đổi (*) | G19: File liên quan | I19: Ghi chú
B20: Added — Thêm mới
B24: Changed — Cải tiến
B28: Fixed — Sửa lỗi
B32: Removed — Xóa bỏ
B37: 💡 BẢNG 3: Nhật ký Prompt AI (PROMPTS)
B38: Mỗi prompt quan trọng ghi 1 block gồm 4 dòng. Ghi rõ prompt đã dùng, kết quả, cách nhóm sử dụng, và kiểm chứng.
B39: Prompt # | C39: TV | D39: Công cụ AI | E39: Prompt đã dùng (nguyên văn) (*)
B40: Prompt #1
B41: Kết quả AI trả về và vấn đề gặp phải:
B42: Nhóm đã chỉnh sửa / sử dụng như thế nào:
B43: Kiểm chứng (test pass/fail, kết quả đúng không):
B44: Prompt #2
B45: Kết quả AI trả về và vấn đề gặp phải:
B46: Nhóm đã chỉnh sửa / sử dụng như thế nào:
B47: Kiểm chứng (test pass/fail, kết quả đúng không):
B48: Prompt #3
B49: Kết quả AI trả về và vấn đề gặp phải:
B50: Nhóm đã chỉnh sửa / sử dụng như thế nào:
B51: Kiểm chứng (test pass/fail, kết quả đúng không):
... B59: Thành viên A — Trưởng nhóm
B60: Đã làm gì trong tuần này? (*) | E60: 💬 Liệt kê cụ thể: tính năng, test case, module, file...
B61: AI đã hỗ trợ như thế nào? | E61: 💬 Tóm tắt cách dùng AI: tool nào, việc gì, hiệu quả ra sao
B62: AI sai hoặc thiếu ở đâu? (*) | E62: 💬 ⚠️ Bắt buộc ≥ 2 ví dụ cụ thể về điểm AI chưa đúng/đủ
B63: Khó khăn gặp phải | E63: 💬 Kỹ thuật, nhóm, công cụ, môi trường...
B64: Nếu làm lại, sẽ cải thiện điều gì? | E64: 💬 Quy trình, cách dùng AI, phân công nhóm...
B66: Thành viên B — Thành viên
B67: Đã làm gì trong tuần này? (*) | E67: 💬 Liệt kê cụ thể: tính năng, test case, module, file...
B68: AI đã hỗ trợ như thế nào? | E68: 💬 Tóm tắt cách dùng AI: tool nào, việc gì, hiệu quả ra sao
B69: AI sai hoặc thiếu ở đâu? (*) | E69: 💬 ⚠️ Bắt buộc ≥ 2 ví dụ cụ thể về điểm AI chưa đúng/đủ
B70: Khó khăn gặp phải | E70: 💬 Kỹ thuật, nhóm, công cụ, môi trường...
B71: Nếu làm lại, sẽ cải thiện điều gì? | E71: 💬 Quy trình, cách dùng AI, phân công nhóm...
B73: Thành viên C — Thành viên
...

Sheet Week_07
B2: WEEK 01 — Nhật ký AI & Project
B3: Mỗi thành viên dùng ký hiệu A/B/C/D/E ở cột TV. Cột (*) bắt buộc điền. Lưu file sau khi điền xong.
B5: 📋 BẢNG 1: Nhật ký sử dụng AI (AI_AUDIT_LOG)
B6: Ghi mỗi lần dùng AI vào 1 dòng. Mức hỗ trợ: Low = AI gợi ý nhỏ | Medium = AI đóng góp nhiều | High = AI tạo phần lớn
B7: Ngày (*) | C7: TV (*) | D7: Công cụ AI (*) | E7: Mục đích sử dụng (*) | F7: File ảnh hưởng | G7: Mức hỗ trợ (*) | H7: Đã chỉnh sửa gì? | I7: Kiểm chứng
B17: 📝 BẢNG 2: Nhật ký thay đổi project (CHANGELOG)
B18: Added = thêm mới | Changed = cải tiến | Fixed = sửa lỗi | Removed = xóa bỏ
B19: Loại (*) | C19: TV (*) | D19: Mô tả thay đổi (*) | G19: File liên quan | I19: Ghi chú
B20: Added — Thêm mới
B24: Changed — Cải tiến
B28: Fixed — Sửa lỗi
B32: Removed — Xóa bỏ
B37: 💡 BẢNG 3: Nhật ký Prompt AI (PROMPTS)
B38: Mỗi prompt quan trọng ghi 1 block gồm 4 dòng. Ghi rõ prompt đã dùng, kết quả, cách nhóm sử dụng, và kiểm chứng.
B39: Prompt # | C39: TV | D39: Công cụ AI | E39: Prompt đã dùng (nguyên văn) (*)
B40: Prompt #1
B41: Kết quả AI trả về và vấn đề gặp phải:
B42: Nhóm đã chỉnh sửa / sử dụng như thế nào:
B43: Kiểm chứng (test pass/fail, kết quả đúng không):
B44: Prompt #2
B45: Kết quả AI trả về và vấn đề gặp phải:
B46: Nhóm đã chỉnh sửa / sử dụng như thế nào:
B47: Kiểm chứng (test pass/fail, kết quả đúng không):
B48: Prompt #3
B49: Kết quả AI trả về và vấn đề gặp phải:
B50: Nhóm đã chỉnh sửa / sử dụng như thế nào:
B51: Kiểm chứng (test pass/fail, kết quả đúng không):
... B59: Thành viên A — Trưởng nhóm
B60: Đã làm gì trong tuần này? (*) | E60: 💬 Liệt kê cụ thể: tính năng, test case, module, file...
B61: AI đã hỗ trợ như thế nào? | E61: 💬 Tóm tắt cách dùng AI: tool nào, việc gì, hiệu quả ra sao
B62: AI sai hoặc thiếu ở đâu? (*) | E62: 💬 ⚠️ Bắt buộc ≥ 2 ví dụ cụ thể về điểm AI chưa đúng/đủ
B63: Khó khăn gặp phải | E63: 💬 Kỹ thuật, nhóm, công cụ, môi trường...
B64: Nếu làm lại, sẽ cải thiện điều gì? | E64: 💬 Quy trình, cách dùng AI, phân công nhóm...
B66: Thành viên B — Thành viên
B67: Đã làm gì trong tuần này? (*) | E67: 💬 Liệt kê cụ thể: tính năng, test case, module, file...
B68: AI đã hỗ trợ như thế nào? | E68: 💬 Tóm tắt cách dùng AI: tool nào, việc gì, hiệu quả ra sao
B69: AI sai hoặc thiếu ở đâu? (*) | E69: 💬 ⚠️ Bắt buộc ≥ 2 ví dụ cụ thể về điểm AI chưa đúng/đủ
B70: Khó khăn gặp phải | E70: 💬 Kỹ thuật, nhóm, công cụ, môi trường...
B71: Nếu làm lại, sẽ cải thiện điều gì? | E71: 💬 Quy trình, cách dùng AI, phân công nhóm...
B73: Thành viên C — Thành viên
...

Sheet Week_08
B2: WEEK 01 — Nhật ký AI & Project
B3: Mỗi thành viên dùng ký hiệu A/B/C/D/E ở cột TV. Cột (*) bắt buộc điền. Lưu file sau khi điền xong.
B5: 📋 BẢNG 1: Nhật ký sử dụng AI (AI_AUDIT_LOG)
B6: Ghi mỗi lần dùng AI vào 1 dòng. Mức hỗ trợ: Low = AI gợi ý nhỏ | Medium = AI đóng góp nhiều | High = AI tạo phần lớn
B7: Ngày (*) | C7: TV (*) | D7: Công cụ AI (*) | E7: Mục đích sử dụng (*) | F7: File ảnh hưởng | G7: Mức hỗ trợ (*) | H7: Đã chỉnh sửa gì? | I7: Kiểm chứng
B17: 📝 BẢNG 2: Nhật ký thay đổi project (CHANGELOG)
B18: Added = thêm mới | Changed = cải tiến | Fixed = sửa lỗi | Removed = xóa bỏ
B19: Loại (*) | C19: TV (*) | D19: Mô tả thay đổi (*) | G19: File liên quan | I19: Ghi chú
B20: Added — Thêm mới
B24: Changed — Cải tiến
B28: Fixed — Sửa lỗi
B32: Removed — Xóa bỏ
B37: 💡 BẢNG 3: Nhật ký Prompt AI (PROMPTS)
B38: Mỗi prompt quan trọng ghi 1 block gồm 4 dòng. Ghi rõ prompt đã dùng, kết quả, cách nhóm sử dụng, và kiểm chứng.
B39: Prompt # | C39: TV | D39: Công cụ AI | E39: Prompt đã dùng (nguyên văn) (*)
B40: Prompt #1
B41: Kết quả AI trả về và vấn đề gặp phải:
B42: Nhóm đã chỉnh sửa / sử dụng như thế nào:
B43: Kiểm chứng (test pass/fail, kết quả đúng không):
B44: Prompt #2
B45: Kết quả AI trả về và vấn đề gặp phải:
B46: Nhóm đã chỉnh sửa / sử dụng như thế nào:
B47: Kiểm chứng (test pass/fail, kết quả đúng không):
B48: Prompt #3
B49: Kết quả AI trả về và vấn đề gặp phải:
B50: Nhóm đã chỉnh sửa / sử dụng như thế nào:
B51: Kiểm chứng (test pass/fail, kết quả đúng không):
... B59: Thành viên A — Trưởng nhóm
B60: Đã làm gì trong tuần này? (*) | E60: 💬 Liệt kê cụ thể: tính năng, test case, module, file...
B61: AI đã hỗ trợ như thế nào? | E61: 💬 Tóm tắt cách dùng AI: tool nào, việc gì, hiệu quả ra sao
B62: AI sai hoặc thiếu ở đâu? (*) | E62: 💬 ⚠️ Bắt buộc ≥ 2 ví dụ cụ thể về điểm AI chưa đúng/đủ
B63: Khó khăn gặp phải | E63: 💬 Kỹ thuật, nhóm, công cụ, môi trường...
B64: Nếu làm lại, sẽ cải thiện điều gì? | E64: 💬 Quy trình, cách dùng AI, phân công nhóm...
B66: Thành viên B — Thành viên
B67: Đã làm gì trong tuần này? (*) | E67: 💬 Liệt kê cụ thể: tính năng, test case, module, file...
B68: AI đã hỗ trợ như thế nào? | E68: 💬 Tóm tắt cách dùng AI: tool nào, việc gì, hiệu quả ra sao
B69: AI sai hoặc thiếu ở đâu? (*) | E69: 💬 ⚠️ Bắt buộc ≥ 2 ví dụ cụ thể về điểm AI chưa đúng/đủ
B70: Khó khăn gặp phải | E70: 💬 Kỹ thuật, nhóm, công cụ, môi trường...
B71: Nếu làm lại, sẽ cải thiện điều gì? | E71: 💬 Quy trình, cách dùng AI, phân công nhóm...
B73: Thành viên C — Thành viên
...

Sheet Week_09
B2: WEEK 01 — Nhật ký AI & Project
B3: Mỗi thành viên dùng ký hiệu A/B/C/D/E ở cột TV. Cột (*) bắt buộc điền. Lưu file sau khi điền xong.
B5: 📋 BẢNG 1: Nhật ký sử dụng AI (AI_AUDIT_LOG)
B6: Ghi mỗi lần dùng AI vào 1 dòng. Mức hỗ trợ: Low = AI gợi ý nhỏ | Medium = AI đóng góp nhiều | High = AI tạo phần lớn
B7: Ngày (*) | C7: TV (*) | D7: Công cụ AI (*) | E7: Mục đích sử dụng (*) | F7: File ảnh hưởng | G7: Mức hỗ trợ (*) | H7: Đã chỉnh sửa gì? | I7: Kiểm chứng
B17: 📝 BẢNG 2: Nhật ký thay đổi project (CHANGELOG)
B18: Added = thêm mới | Changed = cải tiến | Fixed = sửa lỗi | Removed = xóa bỏ
B19: Loại (*) | C19: TV (*) | D19: Mô tả thay đổi (*) | G19: File liên quan | I19: Ghi chú
B20: Added — Thêm mới
B24: Changed — Cải tiến
B28: Fixed — Sửa lỗi
B32: Removed — Xóa bỏ
B37: 💡 BẢNG 3: Nhật ký Prompt AI (PROMPTS)
B38: Mỗi prompt quan trọng ghi 1 block gồm 4 dòng. Ghi rõ prompt đã dùng, kết quả, cách nhóm sử dụng, và kiểm chứng.
B39: Prompt # | C39: TV | D39: Công cụ AI | E39: Prompt đã dùng (nguyên văn) (*)
B40: Prompt #1
B41: Kết quả AI trả về và vấn đề gặp phải:
B42: Nhóm đã chỉnh sửa / sử dụng như thế nào:
B43: Kiểm chứng (test pass/fail, kết quả đúng không):
B44: Prompt #2
B45: Kết quả AI trả về và vấn đề gặp phải:
B46: Nhóm đã chỉnh sửa / sử dụng như thế nào:
B47: Kiểm chứng (test pass/fail, kết quả đúng không):
B48: Prompt #3
B49: Kết quả AI trả về và vấn đề gặp phải:
B50: Nhóm đã chỉnh sửa / sử dụng như thế nào:
B51: Kiểm chứng (test pass/fail, kết quả đúng không):
... B59: Thành viên A — Trưởng nhóm
B60: Đã làm gì trong tuần này? (*) | E60: 💬 Liệt kê cụ thể: tính năng, test case, module, file...
B61: AI đã hỗ trợ như thế nào? | E61: 💬 Tóm tắt cách dùng AI: tool nào, việc gì, hiệu quả ra sao
B62: AI sai hoặc thiếu ở đâu? (*) | E62: 💬 ⚠️ Bắt buộc ≥ 2 ví dụ cụ thể về điểm AI chưa đúng/đủ
B63: Khó khăn gặp phải | E63: 💬 Kỹ thuật, nhóm, công cụ, môi trường...
B64: Nếu làm lại, sẽ cải thiện điều gì? | E64: 💬 Quy trình, cách dùng AI, phân công nhóm...
B66: Thành viên B — Thành viên
B67: Đã làm gì trong tuần này? (*) | E67: 💬 Liệt kê cụ thể: tính năng, test case, module, file...
B68: AI đã hỗ trợ như thế nào? | E68: 💬 Tóm tắt cách dùng AI: tool nào, việc gì, hiệu quả ra sao
B69: AI sai hoặc thiếu ở đâu? (*) | E69: 💬 ⚠️ Bắt buộc ≥ 2 ví dụ cụ thể về điểm AI chưa đúng/đủ
B70: Khó khăn gặp phải | E70: 💬 Kỹ thuật, nhóm, công cụ, môi trường...
B71: Nếu làm lại, sẽ cải thiện điều gì? | E71: 💬 Quy trình, cách dùng AI, phân công nhóm...
B73: Thành viên C — Thành viên
...

Sheet Week_10
B2: WEEK 01 — Nhật ký AI & Project
B3: Mỗi thành viên dùng ký hiệu A/B/C/D/E ở cột TV. Cột (*) bắt buộc điền. Lưu file sau khi điền xong.
B5: 📋 BẢNG 1: Nhật ký sử dụng AI (AI_AUDIT_LOG)
B6: Ghi mỗi lần dùng AI vào 1 dòng. Mức hỗ trợ: Low = AI gợi ý nhỏ | Medium = AI đóng góp nhiều | High = AI tạo phần lớn
B7: Ngày (*) | C7: TV (*) | D7: Công cụ AI (*) | E7: Mục đích sử dụng (*) | F7: File ảnh hưởng | G7: Mức hỗ trợ (*) | H7: Đã chỉnh sửa gì? | I7: Kiểm chứng
B17: 📝 BẢNG 2: Nhật ký thay đổi project (CHANGELOG)
B18: Added = thêm mới | Changed = cải tiến | Fixed = sửa lỗi | Removed = xóa bỏ
B19: Loại (*) | C19: TV (*) | D19: Mô tả thay đổi (*) | G19: File liên quan | I19: Ghi chú
B20: Added — Thêm mới
B24: Changed — Cải tiến
B28: Fixed — Sửa lỗi
B32: Removed — Xóa bỏ
B37: 💡 BẢNG 3: Nhật ký Prompt AI (PROMPTS)
B38: Mỗi prompt quan trọng ghi 1 block gồm 4 dòng. Ghi rõ prompt đã dùng, kết quả, cách nhóm sử dụng, và kiểm chứng.
B39: Prompt # | C39: TV | D39: Công cụ AI | E39: Prompt đã dùng (nguyên văn) (*)
B40: Prompt #1
B41: Kết quả AI trả về và vấn đề gặp phải:
B42: Nhóm đã chỉnh sửa / sử dụng như thế nào:
B43: Kiểm chứng (test pass/fail, kết quả đúng không):
B44: Prompt #2
B45: Kết quả AI trả về và vấn đề gặp phải:
B46: Nhóm đã chỉnh sửa / sử dụng như thế nào:
B47: Kiểm chứng (test pass/fail, kết quả đúng không):
B48: Prompt #3
B49: Kết quả AI trả về và vấn đề gặp phải:
B50: Nhóm đã chỉnh sửa / sử dụng như thế nào:
B51: Kiểm chứng (test pass/fail, kết quả đúng không):
... B59: Thành viên A — Trưởng nhóm
B60: Đã làm gì trong tuần này? (*) | E60: 💬 Liệt kê cụ thể: tính năng, test case, module, file...
B61: AI đã hỗ trợ như thế nào? | E61: 💬 Tóm tắt cách dùng AI: tool nào, việc gì, hiệu quả ra sao
B62: AI sai hoặc thiếu ở đâu? (*) | E62: 💬 ⚠️ Bắt buộc ≥ 2 ví dụ cụ thể về điểm AI chưa đúng/đủ
B63: Khó khăn gặp phải | E63: 💬 Kỹ thuật, nhóm, công cụ, môi trường...
B64: Nếu làm lại, sẽ cải thiện điều gì? | E64: 💬 Quy trình, cách dùng AI, phân công nhóm...
B66: Thành viên B — Thành viên
B67: Đã làm gì trong tuần này? (*) | E67: 💬 Liệt kê cụ thể: tính năng, test case, module, file...
B68: AI đã hỗ trợ như thế nào? | E68: 💬 Tóm tắt cách dùng AI: tool nào, việc gì, hiệu quả ra sao
B69: AI sai hoặc thiếu ở đâu? (*) | E69: 💬 ⚠️ Bắt buộc ≥ 2 ví dụ cụ thể về điểm AI chưa đúng/đủ
B70: Khó khăn gặp phải | E70: 💬 Kỹ thuật, nhóm, công cụ, môi trường...
B71: Nếu làm lại, sẽ cải thiện điều gì? | E71: 💬 Quy trình, cách dùng AI, phân công nhóm...
B73: Thành viên C — Thành viên
...

Sheet Summary
B2: SUMMARY — Tổng hợp cả học kỳ
B4: 📊 Tổng số lần dùng AI theo tuần & thành viên (tự động đếm từ các sheet Week)
B5: Tuần | C5: TV-A | D5: TV-B | E5: TV-C | F5: TV-D | G5: TV-E | H5: Tổng | I5: Low | J5: Medium | K5: High | L5: Ghi chú
B6: Week 01 | C6: =COUNTIF(Week_01!$C$8:$C$15,"A") -> 3 | D6: =COUNTIF(Week_01!$C$8:$C$15,"B") -> 0 | E6: =COUNTIF(Week_01!$C$8:$C$15,"C") -> 0 | F6: =COUNTIF(Week_01!$C$8:$C$15,"D") -> 0 | G6: =COUNTIF(Week_01!$C$8:$C$15,"E") -> 0 | H6: =SUM(C6:G6) -> 3 | I6: =COUNTIF(Week_01!$G$8:$G$15,"Low") -> 0 | J6: =COUNTIF(Week_01!$G$8:$G$15,"Medium") -> 2 | K6: =COUNTIF(Week_01!$G$8:$G$15,"High") -> 1
B7: Week 02 | C7: =COUNTIF(Week_02!$C$8:$C$15,"A") -> 2 | D7: =COUNTIF(Week_02!$C$8:$C$15,"B") -> 0 | E7: =COUNTIF(Week_02!$C$8:$C$15,"C") -> 0 | F7: =COUNTIF(Week_02!$C$8:$C$15,"D") -> 0 | G7: =COUNTIF(Week_02!$C$8:$C$15,"E") -> 0 | H7: =SUM(C7:G7) -> 2 | I7: =COUNTIF(Week_02!$G$8:$G$15,"Low") -> 1 | J7: =COUNTIF(Week_02!$G$8:$G$15,"Medium") -> 1 | K7: =COUNTIF(Week_02!$G$8:$G$15,"High") -> 0
B8: Week 03 | C8: =COUNTIF(Week_03!$C$8:$C$15,"A") -> 2 | D8: =COUNTIF(Week_03!$C$8:$C$15,"B") -> 0 | E8: =COUNTIF(Week_03!$C$8:$C$15,"C") -> 0 | F8: =COUNTIF(Week_03!$C$8:$C$15,"D") -> 0 | G8: =COUNTIF(Week_03!$C$8:$C$15,"E") -> 0 | H8: =SUM(C8:G8) -> 2 | I8: =COUNTIF(Week_03!$G$8:$G$15,"Low") -> 1 | J8: =COUNTIF(Week_03!$G$8:$G$15,"Medium") -> 1 | K8: =COUNTIF(Week_03!$G$8:$G$15,"High") -> 0
B9: Week 04 | C9: =COUNTIF(Week_04!$C$8:$C$15,"A") -> 0 | D9: =COUNTIF(Week_04!$C$8:$C$15,"B") -> 0 | E9: =COUNTIF(Week_04!$C$8:$C$15,"C") -> 0 | F9: =COUNTIF(Week_04!$C$8:$C$15,"D") -> 0 | G9: =COUNTIF(Week_04!$C$8:$C$15,"E") -> 0 | H9: =SUM(C9:G9) -> 0 | I9: =COUNTIF(Week_04!$G$8:$G$15,"Low") -> 0 | J9: =COUNTIF(Week_04!$G$8:$G$15,"Medium") -> 0 | K9: =COUNTIF(Week_04!$G$8:$G$15,"High") -> 0
B10: Week 05 | C10: =COUNTIF(Week_05!$C$8:$C$15,"A") -> 0 | D10: =COUNTIF(Week_05!$C$8:$C$15,"B") -> 0 | E10: =COUNTIF(Week_05!$C$8:$C$15,"C") -> 0 | F10: =COUNTIF(Week_05!$C$8:$C$15,"D") -> 0 | G10: =COUNTIF(Week_05!$C$8:$C$15,"E") -> 0 | H10: =SUM(C10:G10) -> 0 | I10: =COUNTIF(Week_05!$G$8:$G$15,"Low") -> 0 | J10: =COUNTIF(Week_05!$G$8:$G$15,"Medium") -> 0 | K10: =COUNTIF(Week_05!$G$8:$G$15,"High") -> 0
B11: Week 06 | C11: =COUNTIF(Week_06!$C$8:$C$15,"A") -> 0 | D11: =COUNTIF(Week_06!$C$8:$C$15,"B") -> 0 | E11: =COUNTIF(Week_06!$C$8:$C$15,"C") -> 0 | F11: =COUNTIF(Week_06!$C$8:$C$15,"D") -> 0 | G11: =COUNTIF(Week_06!$C$8:$C$15,"E") -> 0 | H11: =SUM(C11:G11) -> 0 | I11: =COUNTIF(Week_06!$G$8:$G$15,"Low") -> 0 | J11: =COUNTIF(Week_06!$G$8:$G$15,"Medium") -> 0 | K11: =COUNTIF(Week_06!$G$8:$G$15,"High") -> 0
B12: Week 07 | C12: =COUNTIF(Week_07!$C$8:$C$15,"A") -> 0 | D12: =COUNTIF(Week_07!$C$8:$C$15,"B") -> 0 | E12: =COUNTIF(Week_07!$C$8:$C$15,"C") -> 0 | F12: =COUNTIF(Week_07!$C$8:$C$15,"D") -> 0 | G12: =COUNTIF(Week_07!$C$8:$C$15,"E") -> 0 | H12: =SUM(C12:G12) -> 0 | I12: =COUNTIF(Week_07!$G$8:$G$15,"Low") -> 0 | J12: =COUNTIF(Week_07!$G$8:$G$15,"Medium") -> 0 | K12: =COUNTIF(Week_07!$G$8:$G$15,"High") -> 0
B13: Week 08 | C13: =COUNTIF(Week_08!$C$8:$C$15,"A") -> 0 | D13: =COUNTIF(Week_08!$C$8:$C$15,"B") -> 0 | E13: =COUNTIF(Week_08!$C$8:$C$15,"C") -> 0 | F13: =COUNTIF(Week_08!$C$8:$C$15,"D") -> 0 | G13: =COUNTIF(Week_08!$C$8:$C$15,"E") -> 0 | H13: =SUM(C13:G13) -> 0 | I13: =COUNTIF(Week_08!$G$8:$G$15,"Low") -> 0 | J13: =COUNTIF(Week_08!$G$8:$G$15,"Medium") -> 0 | K13: =COUNTIF(Week_08!$G$8:$G$15,"High") -> 0
B14: Week 09 | C14: =COUNTIF(Week_09!$C$8:$C$15,"A") -> 0 | D14: =COUNTIF(Week_09!$C$8:$C$15,"B") -> 0 | E14: =COUNTIF(Week_09!$C$8:$C$15,"C") -> 0 | F14: =COUNTIF(Week_09!$C$8:$C$15,"D") -> 0 | G14: =COUNTIF(Week_09!$C$8:$C$15,"E") -> 0 | H14: =SUM(C14:G14) -> 0 | I14: =COUNTIF(Week_09!$G$8:$G$15,"Low") -> 0 | J14: =COUNTIF(Week_09!$G$8:$G$15,"Medium") -> 0 | K14: =COUNTIF(Week_09!$G$8:$G$15,"High") -> 0
B15: Week 10 | C15: =COUNTIF(Week_10!$C$8:$C$15,"A") -> 0 | D15: =COUNTIF(Week_10!$C$8:$C$15,"B") -> 0 | E15: =COUNTIF(Week_10!$C$8:$C$15,"C") -> 0 | F15: =COUNTIF(Week_10!$C$8:$C$15,"D") -> 0 | G15: =COUNTIF(Week_10!$C$8:$C$15,"E") -> 0 | H15: =SUM(C15:G15) -> 0 | I15: =COUNTIF(Week_10!$G$8:$G$15,"Low") -> 0 | J15: =COUNTIF(Week_10!$G$8:$G$15,"Medium") -> 0 | K15: =COUNTIF(Week_10!$G$8:$G$15,"High") -> 0
B16: TỔNG | C16: =SUM(C6:C15) -> 7 | D16: =SUM(D6:D15) -> 0 | E16: =SUM(E6:E15) -> 0 | F16: =SUM(F6:F15) -> 0 | G16: =SUM(G6:G15) -> 0 | H16: =SUM(H6:H15) -> 7 | I16: =SUM(I6:I15) -> 2 | J16: =SUM(J6:J15) -> 4 | K16: =SUM(K6:K15) -> 1
B18: 📝 Nhận xét tổng kết học kỳ của nhóm
B19: Công cụ AI nhóm dùng nhiều nhất:
B20: Tuần sử dụng AI hiệu quả nhất và lý do:
B21: Điểm hạn chế / rủi ro khi dùng AI trong project:
B22: Bài học lớn nhất từ việc dùng AI trong học kỳ này:
